2021-05-29 01:06:12,143 - apscheduler.scheduler - INFO - Scheduler started
2021-05-29 01:06:22,366 - telegram.ext.dispatcher - ERROR - No error handlers are registered, logging exception.
Traceback (most recent call last):
  File "C:\Users\Abhishek\anaconda3\lib\site-packages\urllib3\connection.py", line 159, in _new_conn
    conn = connection.create_connection(
  File "C:\Users\Abhishek\anaconda3\lib\site-packages\urllib3\util\connection.py", line 84, in create_connection
    raise err
  File "C:\Users\Abhishek\anaconda3\lib\site-packages\urllib3\util\connection.py", line 74, in create_connection
    sock.connect(sa)
ConnectionRefusedError: [WinError 10061] No connection could be made because the target machine actively refused it

During handling of the above exception, another exception occurred:

Traceback (most recent call last):
  File "C:\Users\Abhishek\anaconda3\lib\site-packages\urllib3\connectionpool.py", line 670, in urlopen
    httplib_response = self._make_request(
  File "C:\Users\Abhishek\anaconda3\lib\site-packages\urllib3\connectionpool.py", line 392, in _make_request
    conn.request(method, url, **httplib_request_kw)
  File "C:\Users\Abhishek\anaconda3\lib\http\client.py", line 1240, in request
    self._send_request(method, url, body, headers, encode_chunked)
  File "C:\Users\Abhishek\anaconda3\lib\http\client.py", line 1286, in _send_request
    self.endheaders(body, encode_chunked=encode_chunked)
  File "C:\Users\Abhishek\anaconda3\lib\http\client.py", line 1235, in endheaders
    self._send_output(message_body, encode_chunked=encode_chunked)
  File "C:\Users\Abhishek\anaconda3\lib\http\client.py", line 1006, in _send_output
    self.send(msg)
  File "C:\Users\Abhishek\anaconda3\lib\http\client.py", line 946, in send
    self.connect()
  File "C:\Users\Abhishek\anaconda3\lib\site-packages\urllib3\connection.py", line 187, in connect
    conn = self._new_conn()
  File "C:\Users\Abhishek\anaconda3\lib\site-packages\urllib3\connection.py", line 171, in _new_conn
    raise NewConnectionError(
urllib3.exceptions.NewConnectionError: <urllib3.connection.HTTPConnection object at 0x000002825F6E6700>: Failed to establish a new connection: [WinError 10061] No connection could be made because the target machine actively refused it

During handling of the above exception, another exception occurred:

Traceback (most recent call last):
  File "C:\Users\Abhishek\anaconda3\lib\site-packages\requests\adapters.py", line 439, in send
    resp = conn.urlopen(
  File "C:\Users\Abhishek\anaconda3\lib\site-packages\urllib3\connectionpool.py", line 724, in urlopen
    retries = retries.increment(
  File "C:\Users\Abhishek\anaconda3\lib\site-packages\urllib3\util\retry.py", line 439, in increment
    raise MaxRetryError(_pool, url, error or ResponseError(cause))
urllib3.exceptions.MaxRetryError: HTTPConnectionPool(host='127.0.0.1', port=4040): Max retries exceeded with url: /api/tunnels (Caused by NewConnectionError('<urllib3.connection.HTTPConnection object at 0x000002825F6E6700>: Failed to establish a new connection: [WinError 10061] No connection could be made because the target machine actively refused it'))

During handling of the above exception, another exception occurred:

Traceback (most recent call last):
  File "C:\Users\Abhishek\anaconda3\lib\site-packages\telegram\ext\dispatcher.py", line 447, in process_update
    handler.handle_update(update, self, check, context)
  File "C:\Users\Abhishek\anaconda3\lib\site-packages\telegram\ext\handler.py", line 160, in handle_update
    return self.callback(update, context)
  File "c:\Users\Abhishek\Documents\telegram_bot\bot-telegram.py", line 22, in url
    urls = get_public_urls()
  File "c:\Users\Abhishek\Documents\telegram_bot\bot-telegram.py", line 10, in get_public_urls
    response = requests.get(NGROK_URL)
  File "C:\Users\Abhishek\anaconda3\lib\site-packages\requests\api.py", line 76, in get
    return request('get', url, params=params, **kwargs)
  File "C:\Users\Abhishek\anaconda3\lib\site-packages\requests\api.py", line 61, in request
    return session.request(method=method, url=url, **kwargs)
  File "C:\Users\Abhishek\anaconda3\lib\site-packages\requests\sessions.py", line 530, in request
    resp = self.send(prep, **send_kwargs)
  File "C:\Users\Abhishek\anaconda3\lib\site-packages\requests\sessions.py", line 643, in send
    r = adapter.send(request, **kwargs)
  File "C:\Users\Abhishek\anaconda3\lib\site-packages\requests\adapters.py", line 516, in send
    raise ConnectionError(e, request=request)
requests.exceptions.ConnectionError: HTTPConnectionPool(host='127.0.0.1', port=4040): Max retries exceeded with url: /api/tunnels (Caused by NewConnectionError('<urllib3.connection.HTTPConnection object at 0x000002825F6E6700>: Failed to establish a new connection: [WinError 10061] No connection could be made because the target machine actively refused it'))
